<mujoco model="triangle_hinge_model">
    <!-- Set angle units to degrees -->
    <compiler angle="degree" />

    <!-- Simulation options -->
    <option timestep="0.001"
        gravity="0 0 -9.81" />

    <!-- Asset definition with inline mesh -->
    <asset>
        <texture name="grid" type="2d" builtin="checker" rgb1=".1 .2 .3"
            rgb2=".2 .3 .4" width="300" height="300" mark="none" />
        <material name="grid" texture="grid" texrepeat="1 1"
            texuniform="true" reflectance=".2" />

        <!-- Define materials for coloring -->
        <material name="blue_mat" rgba="0 0 1 1" />
        <material name="gray_mat" rgba="0.5 0.5 0.5 1" />

        <mesh name="base_mesh"
            vertex="
             -0.06 -0.034641 0.002      0.06 -0.034641  0.002     0.00  0.069282  0.002
             -0.06 -0.034641 -0.002  0.06 -0.034641 -0.002  0.00  0.069282 -0.002
          " />
        <mesh name="arm_mesh"
            vertex="
             -0.06 -0.034641  0     0.06 -0.034641  0     0.00  0.069282  0
             -0.06 -0.034641 -0.004  0.06 -0.034641 -0.004  0.00  0.069282 -0.004
          " />
    </asset>

    <worldbody>
        <light name="light" pos="0 0 2" diffuse="1 1 1" specular="1 1 1" />
        <geom name="floor" type="plane" pos="0 0 0" size="3 3 .1" material="grid" />
        <camera name="fixed" pos="0 -1.3 .5" xyaxes="1 0 0 0 1 2" />

        <!-- Base body: the centered triangle prism -->
        <body name="base" pos="0 0 0">
            <geom type="mesh" mesh="base_mesh" material="blue_mat" mass="0.1" />
            <joint type="free" name="base_free" />

            <site name="base_site" pos="0 0 0" />

            <!-- <body name="edge1" pos="-0.03 0.0173 -0.002" euler="0 0 -120"> -->
            <body name="edge1" pos="-0.03 0.0173 0.002" euler="90 60 0">
                <joint type="hinge" name="joint1" axis="-1 0 0" range="90 180" damping="0.4" />
                <geom type="mesh" mesh="arm_mesh" material="gray_mat" pos="0 0.034641 0"
                    mass="0.015" />
            </body>

            <body name="edge2" pos="0 -0.03465 -0.002" euler="90 0 0">
                <joint type="hinge" name="joint2" axis="1 0 0" range="90 180" damping="0.4" />
                <geom type="mesh" mesh="arm_mesh" material="gray_mat" pos="0 0.034641 0"
                    mass="0.015" />
            </body>

            <body name="edge3" pos="0.03 0.0173 -0.002" euler="90 120 0">
                <joint type="hinge" name="joint3" axis="1 0 0" range="90 180" damping="0.4" />
                <geom type="mesh" mesh="arm_mesh" material="gray_mat" pos="0 0.034641 0"
                    mass="0.015" />
            </body>
        </body>
    </worldbody>

    <!-- Actuators to control each hinge -->
    <actuator>
        <position name="motor1"
            joint="joint1" gear="1" ctrllimited="true" inheritrange="1" />

        <position name="motor2"
            joint="joint2" gear="1" ctrllimited="true" inheritrange="1" />

        <position name="motor3"
            joint="joint3" gear="1" ctrllimited="true" inheritrange="1" />
    </actuator>

    <sensor>
        <accelerometer name="accel_sensor" site="base_site" />
        <gyro name="gyro_sensor" site="base_site" />
        <magnetometer name="mag_sensor" site="base_site" />
    </sensor>
</mujoco>